2019-07-15 14:21:04,944 ERROR: Exception on /user/test_user [GET] [in /Users/EZ/Documents/git_projects/microblog/venv/lib/python3.7/site-packages/flask/app.py:1780]
Traceback (most recent call last):
  File "/Users/EZ/Documents/git_projects/microblog/venv/lib/python3.7/site-packages/flask/app.py", line 2311, in wsgi_app
    response = self.full_dispatch_request()
  File "/Users/EZ/Documents/git_projects/microblog/venv/lib/python3.7/site-packages/flask/app.py", line 1834, in full_dispatch_request
    rv = self.handle_user_exception(e)
  File "/Users/EZ/Documents/git_projects/microblog/venv/lib/python3.7/site-packages/flask/app.py", line 1737, in handle_user_exception
    reraise(exc_type, exc_value, tb)
  File "/Users/EZ/Documents/git_projects/microblog/venv/lib/python3.7/site-packages/flask/_compat.py", line 36, in reraise
    raise value
  File "/Users/EZ/Documents/git_projects/microblog/venv/lib/python3.7/site-packages/flask/app.py", line 1832, in full_dispatch_request
    rv = self.dispatch_request()
  File "/Users/EZ/Documents/git_projects/microblog/venv/lib/python3.7/site-packages/flask/app.py", line 1818, in dispatch_request
    return self.view_functions[rule.endpoint](**req.view_args)
  File "/Users/EZ/Documents/git_projects/microblog/venv/lib/python3.7/site-packages/flask_login/utils.py", line 261, in decorated_view
    return func(*args, **kwargs)
  File "/Users/EZ/Documents/git_projects/microblog/app/routes.py", line 78, in user_profile
    next_url = url_for('user', username=user.username, page=posts.next_num) if posts.has_next else None
  File "/Users/EZ/Documents/git_projects/microblog/venv/lib/python3.7/site-packages/flask/helpers.py", line 356, in url_for
    return appctx.app.handle_url_build_error(error, endpoint, values)
  File "/Users/EZ/Documents/git_projects/microblog/venv/lib/python3.7/site-packages/flask/app.py", line 2080, in handle_url_build_error
    reraise(exc_type, exc_value, tb)
  File "/Users/EZ/Documents/git_projects/microblog/venv/lib/python3.7/site-packages/flask/_compat.py", line 36, in reraise
    raise value
  File "/Users/EZ/Documents/git_projects/microblog/venv/lib/python3.7/site-packages/flask/helpers.py", line 345, in url_for
    force_external=external)
  File "/Users/EZ/Documents/git_projects/microblog/venv/lib/python3.7/site-packages/werkzeug/routing.py", line 2007, in build
    raise BuildError(endpoint, values, method, self)
werkzeug.routing.BuildError: Could not build url for endpoint 'user' with values ['page', 'username']. Did you mean 'register' instead?
2019-07-15 14:30:52,760 INFO: Microblog startup [in /Users/EZ/Documents/git_projects/microblog/app/__init__.py:44]
2019-07-15 15:09:09,819 INFO: Microblog startup [in /Users/EZ/Documents/git_projects/microblog/app/__init__.py:47]
2019-07-15 15:09:13,129 ERROR: Exception on /login [GET] [in /Users/EZ/Documents/git_projects/microblog/venv/lib/python3.7/site-packages/flask/app.py:1780]
Traceback (most recent call last):
  File "/Users/EZ/Documents/git_projects/microblog/venv/lib/python3.7/site-packages/flask/app.py", line 2311, in wsgi_app
    response = self.full_dispatch_request()
  File "/Users/EZ/Documents/git_projects/microblog/venv/lib/python3.7/site-packages/flask/app.py", line 1834, in full_dispatch_request
    rv = self.handle_user_exception(e)
  File "/Users/EZ/Documents/git_projects/microblog/venv/lib/python3.7/site-packages/flask/app.py", line 1737, in handle_user_exception
    reraise(exc_type, exc_value, tb)
  File "/Users/EZ/Documents/git_projects/microblog/venv/lib/python3.7/site-packages/flask/_compat.py", line 36, in reraise
    raise value
  File "/Users/EZ/Documents/git_projects/microblog/venv/lib/python3.7/site-packages/flask/app.py", line 1832, in full_dispatch_request
    rv = self.dispatch_request()
  File "/Users/EZ/Documents/git_projects/microblog/venv/lib/python3.7/site-packages/flask/app.py", line 1818, in dispatch_request
    return self.view_functions[rule.endpoint](**req.view_args)
  File "/Users/EZ/Documents/git_projects/microblog/app/routes.py", line 48, in login
    return render_template('login.html', title='Sign In', form=form)
  File "/Users/EZ/Documents/git_projects/microblog/venv/lib/python3.7/site-packages/flask/templating.py", line 135, in render_template
    context, ctx.app)
  File "/Users/EZ/Documents/git_projects/microblog/venv/lib/python3.7/site-packages/flask/templating.py", line 117, in _render
    rv = template.render(context)
  File "/Users/EZ/Documents/git_projects/microblog/venv/lib/python3.7/site-packages/jinja2/asyncsupport.py", line 76, in render
    return original_render(self, *args, **kwargs)
  File "/Users/EZ/Documents/git_projects/microblog/venv/lib/python3.7/site-packages/jinja2/environment.py", line 1008, in render
    return self.environment.handle_exception(exc_info, True)
  File "/Users/EZ/Documents/git_projects/microblog/venv/lib/python3.7/site-packages/jinja2/environment.py", line 780, in handle_exception
    reraise(exc_type, exc_value, tb)
  File "/Users/EZ/Documents/git_projects/microblog/venv/lib/python3.7/site-packages/jinja2/_compat.py", line 37, in reraise
    raise value.with_traceback(tb)
  File "/Users/EZ/Documents/git_projects/microblog/app/templates/base.html", line 59, in template
    {% endblock %}
  File "/Users/EZ/Documents/git_projects/microblog/venv/lib/python3.7/site-packages/jinja2/environment.py", line 1005, in render
    return concat(self.root_render_func(self.new_context(vars)))
  File "/Users/EZ/Documents/git_projects/microblog/app/templates/login.html", line 1, in top-level template code
    {% extends "base.html" %}
  File "/Users/EZ/Documents/git_projects/microblog/venv/lib/python3.7/site-packages/jinja2/environment.py", line 780, in handle_exception
    reraise(exc_type, exc_value, tb)
  File "/Users/EZ/Documents/git_projects/microblog/venv/lib/python3.7/site-packages/jinja2/_compat.py", line 37, in reraise
    raise value.with_traceback(tb)
  File "/Users/EZ/Documents/git_projects/microblog/app/templates/base.html", line 59, in template
    {% endblock %}
  File "/Users/EZ/Documents/git_projects/microblog/venv/lib/python3.7/site-packages/jinja2/environment.py", line 497, in _parse
    return Parser(self, source, name, encode_filename(filename)).parse()
  File "/Users/EZ/Documents/git_projects/microblog/venv/lib/python3.7/site-packages/jinja2/parser.py", line 901, in parse
    result = nodes.Template(self.subparse(), lineno=1)
  File "/Users/EZ/Documents/git_projects/microblog/venv/lib/python3.7/site-packages/jinja2/parser.py", line 883, in subparse
    rv = self.parse_statement()
  File "/Users/EZ/Documents/git_projects/microblog/venv/lib/python3.7/site-packages/jinja2/parser.py", line 130, in parse_statement
    return getattr(self, 'parse_' + self.stream.current.value)()
  File "/Users/EZ/Documents/git_projects/microblog/venv/lib/python3.7/site-packages/jinja2/parser.py", line 268, in parse_block
    node.body = self.parse_statements(('name:endblock',), drop_needle=True)
  File "/Users/EZ/Documents/git_projects/microblog/venv/lib/python3.7/site-packages/jinja2/parser.py", line 165, in parse_statements
    result = self.subparse(end_tokens)
  File "/Users/EZ/Documents/git_projects/microblog/venv/lib/python3.7/site-packages/jinja2/parser.py", line 876, in subparse
    self.stream.expect('variable_end')
  File "/Users/EZ/Documents/git_projects/microblog/venv/lib/python3.7/site-packages/jinja2/lexer.py", line 384, in expect
    self.name, self.filename)
jinja2.exceptions.TemplateSyntaxError: expected token 'end of print statement', got '{'
2019-07-15 15:39:30,599 INFO: Microblog startup [in /Users/EZ/Documents/git_projects/microblog/app/__init__.py:49]
