2019-07-26 15:46:27,185 ERROR: Exception on /reindex [GET] [in /Users/EZ/Documents/git_projects/microblog/venv/lib/python3.7/site-packages/flask/app.py:1780]
Traceback (most recent call last):
  File "/Users/EZ/Documents/git_projects/microblog/venv/lib/python3.7/site-packages/sqlalchemy/engine/base.py", line 1244, in _execute_context
    cursor, statement, parameters, context
  File "/Users/EZ/Documents/git_projects/microblog/venv/lib/python3.7/site-packages/sqlalchemy/engine/default.py", line 550, in do_execute
    cursor.execute(statement, parameters)
sqlite3.OperationalError: no such table: post

The above exception was the direct cause of the following exception:

Traceback (most recent call last):
  File "/Users/EZ/Documents/git_projects/microblog/venv/lib/python3.7/site-packages/flask/app.py", line 2311, in wsgi_app
    response = self.full_dispatch_request()
  File "/Users/EZ/Documents/git_projects/microblog/venv/lib/python3.7/site-packages/flask/app.py", line 1834, in full_dispatch_request
    rv = self.handle_user_exception(e)
  File "/Users/EZ/Documents/git_projects/microblog/venv/lib/python3.7/site-packages/flask/app.py", line 1737, in handle_user_exception
    reraise(exc_type, exc_value, tb)
  File "/Users/EZ/Documents/git_projects/microblog/venv/lib/python3.7/site-packages/flask/_compat.py", line 36, in reraise
    raise value
  File "/Users/EZ/Documents/git_projects/microblog/venv/lib/python3.7/site-packages/flask/app.py", line 1832, in full_dispatch_request
    rv = self.dispatch_request()
  File "/Users/EZ/Documents/git_projects/microblog/venv/lib/python3.7/site-packages/flask/app.py", line 1818, in dispatch_request
    return self.view_functions[rule.endpoint](**req.view_args)
  File "/Users/EZ/Documents/git_projects/microblog/app/main/routes.py", line 117, in reindex
    Post.reindex()
  File "/Users/EZ/Documents/git_projects/microblog/app/models.py", line 51, in reindex
    for obj in cls.query:
  File "/Users/EZ/Documents/git_projects/microblog/venv/lib/python3.7/site-packages/sqlalchemy/orm/query.py", line 3323, in __iter__
    return self._execute_and_instances(context)
  File "/Users/EZ/Documents/git_projects/microblog/venv/lib/python3.7/site-packages/sqlalchemy/orm/query.py", line 3348, in _execute_and_instances
    result = conn.execute(querycontext.statement, self._params)
  File "/Users/EZ/Documents/git_projects/microblog/venv/lib/python3.7/site-packages/sqlalchemy/engine/base.py", line 988, in execute
    return meth(self, multiparams, params)
  File "/Users/EZ/Documents/git_projects/microblog/venv/lib/python3.7/site-packages/sqlalchemy/sql/elements.py", line 287, in _execute_on_connection
    return connection._execute_clauseelement(self, multiparams, params)
  File "/Users/EZ/Documents/git_projects/microblog/venv/lib/python3.7/site-packages/sqlalchemy/engine/base.py", line 1107, in _execute_clauseelement
    distilled_params,
  File "/Users/EZ/Documents/git_projects/microblog/venv/lib/python3.7/site-packages/sqlalchemy/engine/base.py", line 1248, in _execute_context
    e, statement, parameters, cursor, context
  File "/Users/EZ/Documents/git_projects/microblog/venv/lib/python3.7/site-packages/sqlalchemy/engine/base.py", line 1466, in _handle_dbapi_exception
    util.raise_from_cause(sqlalchemy_exception, exc_info)
  File "/Users/EZ/Documents/git_projects/microblog/venv/lib/python3.7/site-packages/sqlalchemy/util/compat.py", line 383, in raise_from_cause
    reraise(type(exception), exception, tb=exc_tb, cause=cause)
  File "/Users/EZ/Documents/git_projects/microblog/venv/lib/python3.7/site-packages/sqlalchemy/util/compat.py", line 128, in reraise
    raise value.with_traceback(tb)
  File "/Users/EZ/Documents/git_projects/microblog/venv/lib/python3.7/site-packages/sqlalchemy/engine/base.py", line 1244, in _execute_context
    cursor, statement, parameters, context
  File "/Users/EZ/Documents/git_projects/microblog/venv/lib/python3.7/site-packages/sqlalchemy/engine/default.py", line 550, in do_execute
    cursor.execute(statement, parameters)
sqlalchemy.exc.OperationalError: (sqlite3.OperationalError) no such table: post
[SQL: SELECT post.id AS post_id, post.body AS post_body, post.timestamp AS post_timestamp, post.user_id AS post_user_id, post.language AS post_language 
FROM post]
(Background on this error at: http://sqlalche.me/e/e3q8)
